<?xml version="1.0" encoding="UTF-8"?>
<sdf version='1.9'>  
<model name='x500_base'>
 <pose>0 0 .24 0 0 0</pose>
    <self_collide>false</self_collide>
    <static>false</static>
    <link name='base_link'>
      <inertial>
        <pose>0.00024707 6.1734000000000002e-08 -0.0066068000000000003 0 0 0</pose>
               <mass>2.0</mass>
        <inertia>
          <ixx>0.00023214000000000001</ixx>
          <ixy>6.0879e-09</ixy>
          <ixz>-2.1563000000000001e-14</ixz>
          <iyy>0.00041533999999999999</iyy>
          <iyz>-8.5802999999999994e-15</iyz>
          <izz>0.00051197999999999999</izz>
        </inertia>
      </inertial>
      <gravity>true</gravity>
      <velocity_decay/>
      <collision name='base_link_collision'>
        <pose>0 0 0 0 0 0</pose>
        <geometry>
          <mesh>
            <scale>1 1 1</scale>
            <uri>model://x500_base/meshes/base_link.STL</uri>
          </mesh>
        </geometry>
        <surface>
          <contact>
            <ode>
              <min_depth>0.001</min_depth>
              <max_vel>0</max_vel>
            </ode>
          </contact>
          <friction>
            <ode/>
          </friction>
        </surface>
      </collision>
      <sensor name="air_pressure_sensor" type="air_pressure">
        <always_on>1</always_on>
        <update_rate>50</update_rate>
        <air_pressure>
          <pressure>
            <noise type="gaussian">
              <mean>0</mean>
              <stddev>0.01</stddev>
            </noise>
          </pressure>
        </air_pressure>
      </sensor>
      <sensor name="imu_sensor" type="imu">
        <always_on>1</always_on>
        <update_rate>250</update_rate>
        <imu>
          <angular_velocity>
            <x>
              <noise type="gaussian">
                <mean>0</mean>
                <stddev>0.00018665</stddev>
                <dynamic_bias_stddev>3.8785e-05</dynamic_bias_stddev>
                <dynamic_bias_correlation_time>1000</dynamic_bias_correlation_time>
              </noise>
            </x>
            <y>
              <noise type="gaussian">
                <mean>0</mean>
                <stddev>0.00018665</stddev>
                <dynamic_bias_stddev>3.8785e-05</dynamic_bias_stddev>
                <dynamic_bias_correlation_time>1000</dynamic_bias_correlation_time>
              </noise>
            </y>
            <z>
              <noise type="gaussian">
                <mean>0</mean>
                <stddev>0.00018665</stddev>
                <dynamic_bias_stddev>3.8785e-05</dynamic_bias_stddev>
                <dynamic_bias_correlation_time>1000</dynamic_bias_correlation_time>
              </noise>
            </z>
          </angular_velocity>
          <linear_acceleration>
            <x>
              <noise type="gaussian">
                <mean>0</mean>
                <stddev>0.00186</stddev>
                <dynamic_bias_stddev>0.006</dynamic_bias_stddev>
                <dynamic_bias_correlation_time>300</dynamic_bias_correlation_time>
              </noise>
            </x>
            <y>
              <noise type="gaussian">
                <mean>0</mean>
                <stddev>0.00186</stddev>
                <dynamic_bias_stddev>0.006</dynamic_bias_stddev>
                <dynamic_bias_correlation_time>300</dynamic_bias_correlation_time>
              </noise>
            </y>
            <z>
              <noise type="gaussian">
                <mean>0</mean>
                <stddev>0.00186</stddev>
                <dynamic_bias_stddev>0.006</dynamic_bias_stddev>
                <dynamic_bias_correlation_time>300</dynamic_bias_correlation_time>
              </noise>
            </z>
          </linear_acceleration>
        </imu>
      </sensor>
      <sensor name="navsat_sensor" type="navsat">
        <always_on>1</always_on>
        <update_rate>30</update_rate>
      </sensor>
      <visual name='base_link_visual'>
        <pose>0 0 0 0 0 0</pose>
        <geometry>
          <mesh>
            <scale>1 1 1</scale>
            <uri>model://x500_base/meshes/base_link.STL</uri>
          </mesh>
        </geometry>
        <material>
          <diffuse>0.990199983 1 1 1</diffuse>
          <ambient>0.990199983 1 1 1</ambient>
        </material>
      </visual>
    </link>
    <joint name='rotor_0_joint' type='revolute'>
      <pose relative_to='base_link'>0.17188000000000001 -0.17638999999999999 0.11416999999999999 0 0 0</pose>
      <parent>base_link</parent>
      <child>rotor_0_link</child>
      <axis>
        <xyz>0 0 1</xyz>
        <limit>
           <lower>-1e+16</lower>
          <upper>1e+16</upper>
        </limit>
        <dynamics>
          <spring_reference>0</spring_reference>
          <spring_stiffness>0</spring_stiffness>
        </dynamics>
      </axis>
    </joint>
    <link name='rotor_0_link'>
     <gravity>true</gravity>
      <self_collide>false</self_collide>
      <velocity_decay/>
      <pose relative_to='rotor_0_joint'>0 0 0 0 0 0</pose>
      <inertial>
        <pose>-2.8982000000000001e-08 -2.8279999999999999e-08 0.0061728 0 0 0</pose>
          <mass>0.016076923076923075</mass>     
             <inertia>
          <ixx>8.3965e-06</ixx>
          <ixy>-1.0525e-05</ixy>
          <ixz>6.0789000000000002e-14</ixz>
          <iyy>1.3599e-05</iyy>
          <iyz>-1.0805e-13</iyz>
          <izz>2.1931000000000001e-05</izz>
        </inertia>
      </inertial>
      <collision name='rotor_0_link_collision'>
        <pose>0 0 0 0 0 0</pose>
        <geometry>
          <mesh>
            <scale>1 1 1</scale>
            <uri>model://x500_base/meshes/rotor_0_link.STL</uri>
          </mesh>
        </geometry>
        <surface>
          <contact>
            <ode>
              <min_depth>0.001</min_depth>
              <max_vel>0</max_vel>
            </ode>
          </contact>
          <friction>
            <ode/>
          </friction>
        </surface>
      </collision>
      <visual name='rotor_0_link_visual'>
        <pose>0 0 0 0 0 0</pose>
        <geometry>
          <mesh>
            <scale>1 1 1</scale>
            <uri>model://x500_base/meshes/rotor_0_link.STL</uri>
          </mesh>
        </geometry>
        <material>
          <diffuse>0.990199983 1 1 1</diffuse>
          <ambient>0.990199983 1 1 1</ambient>
        </material>
      </visual>
    </link>
    <joint name='rotor_1_joint' type='revolute'>
      <pose relative_to='base_link'>0.17188000000000001 0.17638000000000001 0.11416999999999999 0 0 0</pose>
      <parent>base_link</parent>
      <child>rotor_1_link</child>
      <axis>
        <xyz>0 0 1</xyz>
        <limit>
         <lower>-1e+16</lower>
          <upper>1e+16</upper>
        </limit>
        <dynamics>
          <spring_reference>0</spring_reference>
          <spring_stiffness>0</spring_stiffness>
        </dynamics>
      </axis>
    </joint>
    <link name='rotor_1_link'>
    <gravity>true</gravity>
      <self_collide>false</self_collide>
      <velocity_decay/>
      <pose relative_to='rotor_1_joint'>0 0 0 0 0 0</pose>
      <inertial>
        <pose>2.8562000000000001e-08 -2.9315000000000001e-08 0.0061728 0 0 0</pose>
          <mass>0.016076923076923075</mass>  
                <inertia>
          <ixx>1.3599e-05</ixx>
          <ixy>1.0525e-05</ixy>
          <ixz>1.0883e-13</ixz>
          <iyy>8.3965e-06</iyy>
          <iyz>5.9861000000000006e-14</iyz>
          <izz>2.1931000000000001e-05</izz>
        </inertia>
      </inertial>
      <collision name='rotor_1_link_collision'>
        <pose>0 0 0 0 0 0</pose>
        <geometry>
          <mesh>
            <scale>1 1 1</scale>
            <uri>model://x500_base/meshes/rotor_1_link.STL</uri>
          </mesh>
        </geometry>
        <surface>
          <contact>
            <ode>
              <min_depth>0.001</min_depth>
              <max_vel>0</max_vel>
            </ode>
          </contact>
          <friction>
            <ode/>
          </friction>
        </surface>
      </collision>
      <visual name='rotor_1_link_visual'>
        <pose>0 0 0 0 0 0</pose>
        <geometry>
          <mesh>
            <scale>1 1 1</scale>
            <uri>model://x500_base/meshes/rotor_1_link.STL</uri>
          </mesh>
        </geometry>
        <material>
          <diffuse>0.990199983 1 1 1</diffuse>
          <ambient>0.990199983 1 1 1</ambient>
        </material>
      </visual>
    </link>
    <joint name='rotor_2_joint' type='revolute'>
      <pose relative_to='base_link'>-0.18089 -0.17638999999999999 0.11416999999999999 0 0 0</pose>
      <parent>base_link</parent>
      <child>rotor_2_link</child>
      <axis>
        <xyz>0 0 1</xyz>
        <limit>
          <lower>-1e+16</lower>
          <upper>1e+16</upper>
        </limit>
        <dynamics>
          <spring_reference>0</spring_reference>
          <spring_stiffness>0</spring_stiffness>
        </dynamics>
      </axis>
    </joint>
    <link name='rotor_2_link'>
    <gravity>true</gravity>
      <self_collide>false</self_collide>
      <velocity_decay/>
      <pose relative_to='rotor_2_joint'>0 0 0 0 0 0</pose>
      <inertial>
        <pose>-2.8562000000000001e-08 2.9315000000000001e-08 0.0061728 0 0 0</pose>
          <mass>0.016076923076923075</mass>
                  <inertia>
          <ixx>1.3599e-05</ixx>
          <ixy>1.0525e-05</ixy>
          <ixz>-1.0883e-13</ixz>
          <iyy>8.3965e-06</iyy>
          <iyz>-5.9861000000000006e-14</iyz>
          <izz>2.1931000000000001e-05</izz>
        </inertia>
      </inertial>
      <collision name='rotor_2_link_collision'>
        <pose>0 0 0 0 0 0</pose>
        <geometry>
          <mesh>
            <scale>1 1 1</scale>
            <uri>model://x500_base/meshes/rotor_2_link.STL</uri>
          </mesh>
        </geometry>
         <surface>
          <contact>
            <ode>
              <min_depth>0.001</min_depth>
              <max_vel>0</max_vel>
            </ode>
          </contact>
          <friction>
            <ode/>
          </friction>
        </surface>
      </collision>
      <visual name='rotor_2_link_visual'>
        <pose>0 0 0 0 0 0</pose>
        <geometry>
          <mesh>
            <scale>1 1 1</scale>
            <uri>model://x500_base/meshes/rotor_2_link.STL</uri>
          </mesh>
        </geometry>
        <material>
          <diffuse>0.990199983 1 1 1</diffuse>
          <ambient>0.990199983 1 1 1</ambient>
        </material>
      </visual>
    </link>
    <joint name='rotor_3_joint' type='revolute'>
      <pose relative_to='base_link'>-0.18089 0.17638000000000001 0.11416999999999999 0 0 0</pose>
      <parent>base_link</parent>
      <child>rotor_3_link</child>
      <axis>
        <xyz>0 0 1</xyz>
        <limit>
         <lower>-1e+16</lower>
          <upper>1e+16</upper>
        </limit>
        <dynamics>
          <spring_reference>0</spring_reference>
          <spring_stiffness>0</spring_stiffness>
        </dynamics>
      </axis>
    </joint>
    <link name='rotor_3_link'>
     <gravity>true</gravity>
      <self_collide>false</self_collide>
      <velocity_decay/>
      <pose relative_to='rotor_3_joint'>0 0 0 0 0 0</pose>
      <inertial>
        <pose>2.8982000000000001e-08 2.8279999999999999e-08 0.0061728 0 0 0</pose>
          <mass>0.016076923076923075</mass>
                  <inertia>
          <ixx>8.3965e-06</ixx>
          <ixy>-1.0525e-05</ixy>
          <ixz>-6.0789000000000002e-14</ixz>
          <iyy>1.3599e-05</iyy>
          <iyz>1.0805e-13</iyz>
          <izz>2.1931000000000001e-05</izz>
        </inertia>
      </inertial>
      <collision name='rotor_3_link_collision'>
        <pose>0 0 0 0 0 0</pose>
        <geometry>
          <mesh>
            <scale>1 1 1</scale>
            <uri>model://x500_base/meshes/rotor_3_link.STL</uri>
          </mesh>
        </geometry>
         <surface>
          <contact>
            <ode>
              <min_depth>0.001</min_depth>
              <max_vel>0</max_vel>
            </ode>
          </contact>
          <friction>
            <ode/>
          </friction>
        </surface>
      </collision>
      <visual name='rotor_3_link_visual'>
        <pose>0 0 0 0 0 0</pose>
        <geometry>
          <mesh>
            <scale>1 1 1</scale>
            <uri>model://x500_base/meshes/rotor_3_link.STL</uri>
          </mesh>
        </geometry>
        <material>
          <diffuse>0.990199983 1 1 1</diffuse>
          <ambient>0.990199983 1 1 1</ambient>
        </material>
      </visual>
    </link>
  </model>
</sdf>
